<?xml version="1.0" ?>
<!-- =================================================================================== -->
<!-- |    This document was autogenerated by xacro from my_robot_integration.urdf.xacro | -->
<!-- |    EDITING THIS FILE BY HAND IS NOT RECOMMENDED                                 | -->
<!-- =================================================================================== -->
<!-- Name your robot here -->
<robot name="">
  <link name="dummy_link"/>
  <joint name="dummy_joint" type="fixed">
    <parent link="dummy_link"/>
    <child link="base_link"/>
    <origin rpy="0 0 0" xyz="0 0 0"/>
    <axis xyz="0 0 0"/>
  </joint>
  <link name="base_link">
    <inertial>
      <origin rpy="0 0 0" xyz="6.13449739986282E-17 -2.84287583232313E-16 0.317524646486478"/>
      <mass value="24.8697261700928"/>
      <inertia ixx="1.43603324810509" ixy="-0.670093087439571" ixz="8.54885606254234E-18" iyy="1.03954854354602" iyz="1.5135190998267E-17" izz="2.4648903764963"/>
    </inertial>
    <visual>
      <origin rpy="0 0 0" xyz="0 0 0"/>
      <geometry>
        <mesh filename="package://Assem3_6/meshes/base_link.STL"/>
      </geometry>
      <material name="">
        <color rgba="0.792156862745098 0.819607843137255 0.933333333333333 1"/>
      </material>
    </visual>
    <collision>
      <origin rpy="0 0 0" xyz="0 0 0"/>
      <geometry>
        <mesh filename="package://Assem3_6/meshes/base_link.STL"/>
      </geometry>
    </collision>
  </link>
  <link name="sup1">
    <inertial>
      <origin rpy="0 0 0" xyz="-5.55111512312578E-17 -0.000177980343412987 -0.138237174654302"/>
      <mass value="0.389772841969077"/>
      <inertia ixx="0.00158921282512124" ixy="1.0842021724855E-19" ixz="8.33480420098232E-19" iyy="0.00242552132363887" iyz="9.14926445411939E-06" izz="0.00100254379468191"/>
    </inertial>
    <visual>
      <origin rpy="0 0 0" xyz="0 0 0"/>
      <geometry>
        <mesh filename="package://Assem3_6/meshes/sup1.STL"/>
      </geometry>
      <material name="">
        <color rgba="0.792156862745098 0.819607843137255 0.933333333333333 1"/>
      </material>
    </visual>
    <collision>
      <origin rpy="0 0 0" xyz="0 0 0"/>
      <geometry>
        <mesh filename="package://Assem3_6/meshes/sup1.STL"/>
      </geometry>
    </collision>
  </link>
  <joint name="sup1j" type="revolute">
    <origin rpy="-3.1416 0 -0.59688" xyz="-0.031134 0.3403 0.0635"/>
    <parent link="base_link"/>
    <child link="sup1"/>
    <axis xyz="0 0 1"/>
    <limit effort="1000" lower="-0.2" upper="0.2" velocity="0.1"/>
  </joint>
  <link name="wheel_fl">
    <inertial>
      <origin rpy="0 0 0" xyz="0.00233486260762672 2.77555756156289E-17 -0.0634570596277791"/>
      <mass value="1.46839033896977"/>
      <inertia ixx="0.00504783706093038" ixy="-9.77591214033663E-18" ixz="-0.000129476629479786" iyy="0.00504307304976272" iyz="-2.14566791214805E-18" izz="0.00856199796228847"/>
    </inertial>
    <visual>
      <origin rpy="0 0 0" xyz="0 0 0"/>
      <geometry>
        <mesh filename="package://Assem3_6/meshes/wheel_fl.STL"/>
      </geometry>
      <material name="">
        <color rgba="0.792156862745098 0.819607843137255 0.933333333333333 1"/>
      </material>
    </visual>
    <collision>
      <origin rpy="0 0 0" xyz="0 0 0"/>
      <geometry>
        <mesh filename="package://Assem3_6/meshes/wheel_fl.STL"/>
      </geometry>
    </collision>
  </link>
  <joint name="wheel_flj" type="continuous">
    <origin rpy="-1.5708 0 -1.6076" xyz="0.0635 0 -0.0381"/>
    <parent link="sup1"/>
    <child link="wheel_fl"/>
    <axis xyz="-0.076302 0 0.99708"/>
  </joint>
  <link name="sup2">
    <inertial>
      <origin rpy="0 0 0" xyz="2.77555756156289E-17 -0.000177980343413098 -0.138237174654302"/>
      <mass value="0.389772841969076"/>
      <inertia ixx="0.00158921282512124" ixy="5.42101086242752E-20" ixz="-2.96461531539005E-20" iyy="0.00242552132363886" iyz="9.14926445411846E-06" izz="0.00100254379468192"/>
    </inertial>
    <visual>
      <origin rpy="0 0 0" xyz="0 0 0"/>
      <geometry>
        <mesh filename="package://Assem3_6/meshes/sup2.STL"/>
      </geometry>
      <material name="">
        <color rgba="0.792156862745098 0.819607843137255 0.933333333333333 1"/>
      </material>
    </visual>
    <collision>
      <origin rpy="0 0 0" xyz="0 0 0"/>
      <geometry>
        <mesh filename="package://Assem3_6/meshes/sup2.STL"/>
      </geometry>
    </collision>
  </link>
  <joint name="sup2j" type="revolute">
    <origin rpy="3.1416 0 2.5815" xyz="0.33515 0.066684 0.0635"/>
    <parent link="base_link"/>
    <child link="sup2"/>
    <axis xyz="0 0 1"/>
    <limit effort="1000" lower="-0.2" upper="0.2" velocity="0.1"/>
  </joint>
  <link name="wheel_fr">
    <inertial>
      <origin rpy="0 0 0" xyz="0.00233486260762675 -2.77555756156289E-17 0.063457059627779"/>
      <mass value="1.46839033896977"/>
      <inertia ixx="0.00504783706093039" ixy="-6.03691754274001E-18" ixz="0.000129476629479785" iyy="0.00504307304976271" iyz="-1.09334056044605E-18" izz="0.00856199796228847"/>
    </inertial>
    <visual>
      <origin rpy="0 0 0" xyz="0 0 0"/>
      <geometry>
        <mesh filename="package://Assem3_6/meshes/wheel_fr.STL"/>
      </geometry>
      <material name="">
        <color rgba="0.792156862745098 0.819607843137255 0.933333333333333 1"/>
      </material>
    </visual>
    <collision>
      <origin rpy="0 0 0" xyz="0 0 0"/>
      <geometry>
        <mesh filename="package://Assem3_6/meshes/wheel_fr.STL"/>
      </geometry>
    </collision>
  </link>
  <joint name="wheel_frj" type="continuous">
    <origin rpy="-1.5708 0 -1.534" xyz="-0.0635 0 -0.0381"/>
    <parent link="sup2"/>
    <child link="wheel_fr"/>
    <axis xyz="0.039588 0 -0.99922"/>
  </joint>
  <link name="sup3">
    <inertial>
      <origin rpy="0 0 0" xyz="-0.0635000000000001 0.0252220196565872 0.0649628253456976"/>
      <mass value="0.389772841969077"/>
      <inertia ixx="0.00158921282512123" ixy="1.62630325872826E-19" ixz="-3.71847463844638E-19" iyy="0.00242552132363887" iyz="9.14926445411925E-06" izz="0.00100254379468191"/>
    </inertial>
    <visual>
      <origin rpy="0 0 0" xyz="0 0 0"/>
      <geometry>
        <mesh filename="package://Assem3_6/meshes/sup3.STL"/>
      </geometry>
      <material name="">
        <color rgba="0.792156862745098 0.819607843137255 0.933333333333333 1"/>
      </material>
    </visual>
    <collision>
      <origin rpy="0 0 0" xyz="0 0 0"/>
      <geometry>
        <mesh filename="package://Assem3_6/meshes/sup3.STL"/>
      </geometry>
    </collision>
  </link>
  <joint name="sup3j" type="fixed">
    <origin rpy="-3.1416 0 -0.64158" xyz="-0.26908 -0.084337 0.2667"/>
    <parent link="base_link"/>
    <child link="sup3"/>
    <axis xyz="0 0 0"/>
  </joint>
  <link name="wheel_bl">
    <inertial>
      <origin rpy="0 0 0" xyz="-5.55111512312578E-17 5.55111512312578E-17 0.0635"/>
      <mass value="1.46839033896977"/>
      <inertia ixx="0.00504307304976271" ixy="-9.70245380481909E-18" ixz="-2.16840434497101E-19" iyy="0.00504307304976271" iyz="-1.19925513509158E-19" izz="0.00856676197345612"/>
    </inertial>
    <visual>
      <origin rpy="0 0 0" xyz="0 0 0"/>
      <geometry>
        <mesh filename="package://Assem3_6/meshes/wheel_bl.STL"/>
      </geometry>
      <material name="">
        <color rgba="0.792156862745098 0.819607843137255 0.933333333333333 1"/>
      </material>
    </visual>
    <collision>
      <origin rpy="0 0 0" xyz="0 0 0"/>
      <geometry>
        <mesh filename="package://Assem3_6/meshes/wheel_bl.STL"/>
      </geometry>
    </collision>
  </link>
  <joint name="wheel_blj" type="continuous">
    <origin rpy="-1.5708 0 -1.5708" xyz="-0.127 0.0254 0.1651"/>
    <parent link="sup3"/>
    <child link="wheel_bl"/>
    <axis xyz="0 0 -1"/>
  </joint>
  <link name="sup4">
    <inertial>
      <origin rpy="0 0 0" xyz="-0.0635 0.0252220196565871 0.0649628253456977"/>
      <mass value="0.389772841969076"/>
      <inertia ixx="0.00158921282512123" ixy="2.16840434497101E-19" ixz="-2.43945488809238E-19" iyy="0.00242552132363886" iyz="9.14926445411836E-06" izz="0.00100254379468191"/>
    </inertial>
    <visual>
      <origin rpy="0 0 0" xyz="0 0 0"/>
      <geometry>
        <mesh filename="package://Assem3_6/meshes/sup4.STL"/>
      </geometry>
      <material name="">
        <color rgba="0.792156862745098 0.819607843137255 0.933333333333333 1"/>
      </material>
    </visual>
    <collision>
      <origin rpy="0 0 0" xyz="0 0 0"/>
      <geometry>
        <mesh filename="package://Assem3_6/meshes/sup4.STL"/>
      </geometry>
    </collision>
  </link>
  <joint name="sup4j" type="fixed">
    <origin rpy="3.1416 0 2.5" xyz="-0.03494 -0.32265 0.2667"/>
    <parent link="base_link"/>
    <child link="sup4"/>
    <axis xyz="0 0 0"/>
  </joint>
  <link name="wheel_br">
    <inertial>
      <origin rpy="0 0 0" xyz="5.55111512312578E-17 0 0.0635"/>
      <mass value="1.46839033896977"/>
      <inertia ixx="0.00504307304976272" ixy="-4.48171774300226E-18" ixz="2.60208521396521E-18" iyy="0.00504307304976271" iyz="-7.41249960609166E-19" izz="0.00856676197345613"/>
    </inertial>
    <visual>
      <origin rpy="0 0 0" xyz="0 0 0"/>
      <geometry>
        <mesh filename="package://Assem3_6/meshes/wheel_br.STL"/>
      </geometry>
      <material name="">
        <color rgba="0.792156862745098 0.819607843137255 0.933333333333333 1"/>
      </material>
    </visual>
    <collision>
      <origin rpy="0 0 0" xyz="0 0 0"/>
      <geometry>
        <mesh filename="package://Assem3_6/meshes/wheel_br.STL"/>
      </geometry>
    </collision>
  </link>
  <joint name="wheel_brj" type="continuous">
    <origin rpy="-1.5708 0 -1.5708" xyz="-0.127 0.0254 0.1651"/>
    <parent link="sup4"/>
    <child link="wheel_br"/>
    <axis xyz="0 0 1"/>
  </joint>
  <transmission name="fl">
    <type>transmission_interface/SimpleTransmission</type>
    <joint name="wheel_flj">
      <hardwareInterface>hardware_interface/EffortJointInterface</hardwareInterface>
    </joint>
    <actuator name="motor_fl">
      <hardwareInterface>hardware_interface/EffortJointInterface</hardwareInterface>
      <mechanicalReduction>1</mechanicalReduction>
    </actuator>
  </transmission>
  <transmission name="fr">
    <type>transmission_interface/SimpleTransmission</type>
    <joint name="wheel_frj">
      <hardwareInterface>hardware_interface/EffortJointInterface</hardwareInterface>
    </joint>
    <actuator name="motor_fr">
      <hardwareInterface>hardware_interface/EffortJointInterface</hardwareInterface>
      <mechanicalReduction>1</mechanicalReduction>
    </actuator>
  </transmission>
  <transmission name="bl">
    <type>transmission_interface/SimpleTransmission</type>
    <joint name="wheel_blj">
      <hardwareInterface>hardware_interface/VelocityJointInterface</hardwareInterface>
    </joint>
    <actuator name="motor_bl">
      <hardwareInterface>hardware_interface/VelocityJointInterface</hardwareInterface>
      <mechanicalReduction>1</mechanicalReduction>
    </actuator>
  </transmission>
  <transmission name="br">
    <type>transmission_interface/SimpleTransmission</type>
    <joint name="wheel_brj">
      <hardwareInterface>hardware_interface/VelocityJointInterface</hardwareInterface>
    </joint>
    <actuator name="motor_br">
      <hardwareInterface>hardware_interface/VelocityJointInterface</hardwareInterface>
      <mechanicalReduction>1</mechanicalReduction>
    </actuator>
  </transmission>
  <link name="base_laser">
    <inertial>
      <origin rpy="0 0 0" xyz="-0.00029774 0.0066667 0.00013047"/>
      <mass value="0.15717"/>
      <inertia ixx="6.7885E-05" ixy="-1.3987E-07" ixz="-8.1554E-07" iyy="0.00013173" iyz="-9.0932E-08" izz="7.1972E-05"/>
    </inertial>
    <visual>
      <origin rpy="0 0 0" xyz="0 0 0"/>
      <geometry>
        <mesh filename="package://Assem3_6/meshes/ydlidar.dae"/>
      </geometry>
      <material name="">
        <color rgba="0.64706 0.61961 0.58824 1"/>
      </material>
    </visual>
    <collision>
      <origin rpy="0 0 0" xyz="0 0 0"/>
      <geometry>
        <mesh filename="package://Assem3_6/meshes/ydlidar.dae"/>
      </geometry>
    </collision>
  </link>
  <link name="laser_frame">
    <inertial>
      <origin rpy="0 0 0" xyz="-0.00036659 0.00064155 -0.00027052"/>
      <mass value="0.25482"/>
      <inertia ixx="8.9194E-05" ixy="1.8116E-07" ixz="3.6435E-08" iyy="0.00018279" iyz="2.423E-07" izz="0.00011103"/>
    </inertial>
    <!--visual>
      <origin
        xyz="0 0 0"
        rpy="0 0 0" />
      <geometry>
        <mesh
          filename="package://Assem3_6/meshes/ydlidar.dae" />
      </geometry>
      <material
        name="">
        <color
          rgba="0.64706 0.61961 0.58824 1" />
      </material>
    </visual-->
    <!--collision>
      <origin
        xyz="0 0 0"
        rpy="0 0 0" />
      <geometry>
        <mesh
          filename="package://Assem3_6/meshes/ydlidar.dae" />
      </geometry>
    </collision-->
  </link>
  <joint name="laser_joint" type="fixed">
    <origin rpy="0 0 0" xyz="0 0 0.03172"/>
    <parent link="base_laser"/>
    <child link="laser_frame"/>
    <axis xyz="0 0 0"/>
  </joint>
  <!-- Add your gazebo sensors here -->
  <gazebo reference="base_laser">
    <!-- <gravity>true</gravity> -->
    <!-- Gazebo has fixed set of Sensors types. Check them out here <> -->
    <sensor name="laser" type="ray">
      <!-- Add in your sensor characteristics -->
      <pose> 0 0 0 0 0 0 </pose>
      <visualise>true</visualise>
      <update_rate>40</update_rate>
      <!-- <always_on>true</always_on> -->
      <ray>
        <scan>
          <horizontal>
            <samples>720</samples>
            <resolution>1</resolution>
            <min_angle>-1.570796</min_angle>
            <max_angle>1.570796</max_angle>
          </horizontal>
        </scan>
        <range>
          <min>0.10</min>
          <max>30.0</max>
          <resolution>0.01</resolution>
        </range>
        <noise>
          <type>gaussian</type>
          <mean>0.0</mean>
          <stddev>0.01</stddev>
        </noise>
      </ray>
      <plugin filename="libgazebo_ros_laser.so" name="gazebo_ros_head_hokuyo_controller">
        <!-- Use topic name as /my_robot/scan -->
        <topicName>/Assem3_6/scan</topicName>
        <frameName>laser_frame</frameName>
      </plugin>
    </sensor>
  </gazebo>
  <!--  Gazebo plugin for control here is already added for you -->
  <gazebo>
    <plugin filename="libgazebo_ros_control.so" name="gazebo_ros_control">
      <robotNamespace>/Assem3_6</robotNamespace>
      <robotSimType>gazebo_ros_control/DefaultRobotHWSim</robotSimType>
      <legacyModeNS>true</legacyModeNS>
    </plugin>
  </gazebo>
  <!-- Create a joint between your robot and sensor -->
  <joint name="lidar_car_joint" type="fixed">
    <axis xyz="0 0 1"/>
    <origin rpy="0 0 0" xyz="0 0 0.545"/>
    <parent link="base_link"/>
    <child link="base_laser"/>
  </joint>
</robot>
